<?xml version="1.0"?>
	<robot name="forklift">
		<link name="base_link">
			<visual>
				<origin rpy="1.57075 0 0" xyz="-0.38 1.38 0"/>
				<geometry>
					<mesh filename="package://forklift_description/meshes/main_chasis.STL" scale="0.001 0.001 0.001"/>
				</geometry>
				<material name="black">
       			<color rgba="0.3 1 0.3 1"/>
     			</material>
			</visual>
		</link>	
		<link name="column">
			<visual>
				<origin rpy="1.57075 0 3.1415 " xyz="0.1 -0.07 0.25"/>
				<geometry>
					<mesh filename="package://forklift_description/meshes/column.STL" scale="0.001 0.001 0.001"/>
				</geometry>
				<material name="grey">
       			<color rgba="0.1 0 1 1"/>
     			</material>
			</visual>
		</link>
		<joint name="steering" type="revolute">
			<axis xyz="0 0 1"/>
            <limit effort="1000.0" lower="-1.57075" upper="1.57075" velocity="0.5"/>
			<parent link="base_link"/>
			<child link="column"/>
			<origin xyz="0 0 0"/>
		</joint>
		<link name="mounting_wheel">
			<visual>
				<origin rpy="1.57075 0 3.1415" xyz="0.11 -0.07 0.055"/>
				<geometry>
					<mesh filename="package://forklift_description/meshes/mount_wheel.STL" scale="0.001 0.001 0.001"/>
				</geometry>
				<material name="grey">
       			<color rgba="0.3 1 0.3 0.5"/>
     			</material>
			</visual>
		</link>
		<joint name="column_to_mounting_wheel" type="fixed">
			<parent link="column"/>
			<child link="mounting_wheel"/>
			<origin xyz="0 0 0"/>
		</joint>
		<link name="motor">
			<visual>
				<origin rpy="1.57075 0 3.1415" xyz="0.05 -0.065 -0.07"/>
				<geometry>
					<mesh filename="package://forklift_description/meshes/driving_motor.STL" scale="0.001 0.001 0.001"/>
				</geometry>
				<material name="grey">
       			<color rgba="0.3 0.3 0.3 1"/>
     			</material>
			</visual>
		</link>
		<joint name="mounting_wheel_to_motor" type="fixed">
			<parent link="mounting_wheel"/>
			<child link="motor"/>
			<origin xyz="0 0 0.1"/>
		</joint>
		<link name="driving_wheel">
			<visual>
				<origin rpy="0 0 0" xyz="-0.035 -0.125 -0.125"/>
				<geometry>
					<mesh filename="package://forklift_description/meshes/driving_wheel.STL" scale="0.001 0.001 0.001"/>
				</geometry>
				<material name="grey">
       			<color rgba="0.3 0.3 0.3 1"/>
     			</material>
			</visual>
		</link>
		<joint name="column_to_driving_wheel" type="fixed">
			<parent link="column"/>
			<child link="driving_wheel"/>
			<origin xyz="0 0 0"/>
		</joint>
		<joint name="driving_wheel" type="continuous">
			<axis xyz="1 0 0"/>
            <limit effort="1000.0" lower="-3.14" upper="3.14" velocity="0.5"/>
			<parent link="motor"/>
			<child link="driving_wheel"/>
			<origin xyz="0 0 0"/>
		</joint>
		<link name="fork_mount">
			<visual>
				<origin rpy="1.57075 0 1.57075 " xyz="-0.5 -0.05 0.1"/>
				<geometry>
					<mesh filename="package://forklift_description/meshes/fork_holder.STL" scale="0.001 0.001 0.001"/>
				</geometry>
				<material name="grey">
       			<color rgba="0.1 0 1 1"/>
     			</material>
			</visual>
		</link>
		<joint name="fork" type="prismatic">
			<axis xyz="0 0 1"/>
            <limit effort="1000.0" lower="0" upper="1.4" velocity="0.5"/>
			<parent link="base_link"/>
			<child link="fork_mount"/>
			<origin xyz="0 0.5 0"/>
		</joint>
		<link name="fork_left">
			<visual>
				<origin rpy="1.57075 0 1.57075" xyz="-0.07 -0.04 -0.41"/>
				<geometry>
					<mesh filename="package://forklift_description/meshes/fork.STL" scale="0.001 0.001 0.001"/>
				</geometry>
				<material name="grey">
       			<color rgba="0.3 0.3 0.3 1"/>
     			</material>
			</visual>
		</link>
		<joint name="fork_left_left" type="fixed">
			<parent link="fork_mount"/>
			<child link="fork_left"/>
			<origin xyz="-0.26 0.09 0.47"/>
		</joint>
		<link name="fork_right">
			<visual>
				<origin rpy="1.57075 0 1.57075" xyz="-0.07 -0.04 -0.41"/>
				<geometry>
					<mesh filename="package://forklift_description/meshes/fork.STL" scale="0.001 0.001 0.001"/>
				</geometry>
				<material name="grey">
       			<color rgba="0.3 0.3 0.3 1"/>
     			</material>
			</visual>
		</link>
		<joint name="fork_right_right" type="fixed">
			<parent link="fork_mount"/>
			<child link="fork_right"/>
			<origin xyz="0.26 0.09 0.47"/>
		</joint>
	</robot>
